# BATCH10_PROMPT15_Devstral.py

import sys
import traceback
from functools import wraps

class PredictiveErrorHandler:
    """A decorator that logs potential errors that could occur in a function."""

    @staticmethod
    def log_potential_errors(func):
        """Decorator to log what error would have occurred."""
        @wraps(func)
        def wrapper(*args, **kwargs):
            try:
                # Try running the function normally
                return func(*args, **kwargs)
            except Exception as e:
                # If an actual exception occurs, log it and re-raise
                print(f"Actual error occurred: {type(e).__name__}: {e}")
                raise
        return wrapper

    @staticmethod
    def predict_errors(func):
        """Analyzes the function to predict potential errors."""
        try:
            # This is a simplified prediction - in reality, static analysis would be more complex
            # Here we just check for common patterns that might cause errors
            code = func.__code__
            if 'ZeroDivisionError' in func.__name__ or any(
                op == 'BINARY_DIVIDE' and argval == 0
                for op, argval in zip(code.co_code, range(code.co_nlocals))
                if op == 'BINARY_DIVIDE'
            ):
                print(f"Predicted ZeroDivisionError in function: {func.__name__}")
        except Exception as e:
            print(f"Error during error prediction analysis: {type(e).__name__}: {e}")

def main():
    """Demonstration of the Predictive Error Handler."""

    @PredictiveErrorHandler.log_potential_errors
    def safe_division(x, y):
        return x / y

    @PredictiveErrorHandler.log_potential_errors
    def risky_division(x, y):
        # This will cause a ZeroDivisionError
        return x / (y - y)

    print("Testing safe division:")
    result = safe_division(10, 2)
    print(f"Result: {result}")

    print("\nTesting risky division:")
    try:
        result = risky_division(10, 5)  # This should trigger the actual error
    except Exception as e:
        print(f"Handled exception: {type(e).__name__}: {e}")

    print("\nPredicting errors in functions:")
    PredictiveErrorHandler.predict_errors(safe_division)
    PredictiveErrorHandler.predict_errors(risky_division)

if __name__ == "__main__":
    main()

# ===== GENERATED TESTS =====
# BATCH10_PROMPT15_Devstral.py

import sys
import traceback
from functools import wraps

class PredictiveErrorHandler:
    """A decorator that logs potential errors that could occur in a function."""

    @staticmethod
    def log_potential_errors(func):
        """Decorator to log what error would have occurred."""
        @wraps(func)
        def wrapper(*args, **kwargs):
            try:
                # Try running the function normally
                return func(*args, **kwargs)
            except Exception as e:
                # If an actual exception occurs, log it and re-raise
                print(f"Actual error occurred: {type(e).__name__}: {e}")
                raise
        return wrapper

    @staticmethod
    def predict_errors(func):
        """Analyzes the function to predict potential errors."""
        try:
            # This is a simplified prediction - in reality, static analysis would be more complex
            # Here we just check for common patterns that might cause errors
            code = func.__code__
            if 'ZeroDivisionError' in func.__name__ or any(
                op == 'BINARY_DIVIDE' and argval == 0
                for op, argval in zip(code.co_code, range(code.co_nlocals))
                if op == 'BINARY_DIVIDE'
            ):
                print(f"Predicted ZeroDivisionError in function: {func.__name__}")
        except Exception as e:
            print(f"Error during error prediction analysis: {type(e).__name__}: {e}")

def main():
    """Demonstration of the Predictive Error Handler."""

    @PredictiveErrorHandler.log_potential_errors
    def safe_division(x, y):
        return x / y

    @PredictiveErrorHandler.log_potential_errors
    def risky_division(x, y):
        # This will cause a ZeroDivisionError
        return x / (y - y)

    print("Testing safe division:")
    result = safe_division(10, 2)
    print(f"Result: {result}")

    print("\nTesting risky division:")
    try:
        result = risky_division(10, 5)  # This should trigger the actual error
    except Exception as e:
        print(f"Handled exception: {type(e).__name__}: {e}")

    print("\nPredicting errors in functions:")
    PredictiveErrorHandler.predict_errors(safe_division)
    PredictiveErrorHandler.predict_errors(risky_division)

if __name__ == "__main__":
    main()

# Test suite for BATCH10_PROMPT15_Devstral.py

import pytest
from BATCH10_PROMPT15_Devstral import PredictiveErrorHandler, safe_division, risky_division

def test_safe_division():
    """Test the safe_division function."""
    assert safe_division(10, 2) == 5.0
    with pytest.raises(ZeroDivisionError):
        safe_division(10, 0)

def test_risky_division():
    """Test the risky_division function."""
    with pytest.raises(ZeroDivisionError):
        risky_division(10, 5)

def test_predict_errors():
    """Test the predict_errors method."""
    def zero_division_func(x, y):
        return x / (y - y)
    
    PredictiveErrorHandler.predict_errors(zero_division_func)
    # The output of predict_errors is printed to the console, so we cannot directly assert it
    # Instead, we can check if the function runs without raising an exception

def test_predict_errors_no_error():
    """Test the predict_errors method with a function that does not raise an error."""
    def no_division_func(x, y):
        return x + y
    
    PredictiveErrorHandler.predict_errors(no_division_func)
    # The output of predict_errors is printed to the console, so we cannot directly assert it
    # Instead, we can check if the function runs without raising an exception

# Run the tests
if __name__ == "__main__":
    pytest.main()
